Workbook

Sheet raw_data
A2: Mobile Legends: Bang Bang
A3: Grafis & Desain | B3: Keseimbangan Gameplay | C3: Popularitas & Komunitas | D3: Stabilitas server/koneksi | E3: Fitur & Mode | F3: Kemudahan Kontrol & UI | G3: Tingkat Kompetitif | H3: Sistem Pembayaran | I3: Ukuran Aplikasi | J3: Lancar di HP Menengah | K3: Fairness F2P | L3: Sosialisasi/Menambah Kenalan | M3: Rekomendasi Untuk Pemula
A4: 5 | B4: 4 | C4: 4 | D4: 4 | E4: 5 | F4: 4 | G4: 4 | H4: 3 | I4: 3 | J4: 3 | K4: 4 | L4: 4 | M4: 5
A5: 4 | B5: 3 | C5: 4 | D5: 2 | E5: 4 | F5: 4 | G5: 3 | H5: 3 | I5: 3 | J5: 3 | K5: 4 | L5: 3 | M5: 5
A6: 5 | B6: 4 | C6: 5 | D6: 4 | E6: 5 | F6: 4 | G6: 4 | H6: 4 | I6: 3 | J6: 3 | K6: 3 | L6: 5 | M6: 5
A7: 4 | B7: 4 | C7: 3 | D7: 4 | E7: 4 | F7: 4 | G7: 5 | H7: 3 | I7: 2 | J7: 4 | K7: 5 | L7: 4 | M7: 5
A8: 5 | B8: 5 | C8: 5 | D8: 4 | E8: 4 | F8: 4 | G8: 5 | H8: 4 | I8: 5 | J8: 5 | K8: 4 | L8: 5 | M8: 5
A9: 4 | B9: 5 | C9: 5 | D9: 4 | E9: 5 | F9: 4 | G9: 5 | H9: 5 | I9: 5 | J9: 3 | K9: 3 | L9: 5 | M9: 4
A10: 5 | B10: 3 | C10: 5 | D10: 3 | E10: 4 | F10: 5 | G10: 4 | H10: 5 | I10: 4 | J10: 4 | K10: 4 | L10: 3 | M10: 4
A11: 4 | B11: 4 | C11: 5 | D11: 4 | E11: 4 | F11: 4 | G11: 5 | H11: 5 | I11: 4 | J11: 4 | K11: 4 | L11: 3 | M11: 4
A12: 4 | B12: 4 | C12: 4 | D12: 4 | E12: 4 | F12: 5 | G12: 4 | H12: 4 | I12: 4 | J12: 4 | K12: 4 | L12: 4 | M12: 4
A13: 3 | B13: 3 | C13: 3 | D13: 3 | E13: 3 | F13: 3 | G13: 3 | H13: 3 | I13: 3 | J13: 3 | K13: 3 | L13: 3 | M13: 3
A14: 4 | B14: 4 | C14: 4 | D14: 3 | E14: 4 | F14: 4 | G14: 4 | H14: 3 | I14: 3 | J14: 3 | K14: 3 | L14: 4 | M14: 4
A15: 4 | B15: 5 | C15: 5 | D15: 4 | E15: 5 | F15: 5 | G15: 5 | H15: 5 | I15: 3 | J15: 4 | K15: 4 | L15: 4 | M15: 3
... A30: 5 | B30: 5 | C30: 5 | D30: 4 | E30: 4 | F30: 4 | G30: 5 | H30: 4 | I30: 4 | J30: 3 | K30: 4 | L30: 2 | M30: 2
A31: =GEOMEAN(A4:A30) -> 4.2079494 | B31: =GEOMEAN(B4:B30) -> 3.7932954 | C31: =GEOMEAN(C4:C30) -> 4.2995074 | D31: =GEOMEAN(D4:D30) -> 3.5909147 | E31: =GEOMEAN(E4:E30) -> 4.2780812 | F31: =GEOMEAN(F4:F30) -> 4.3493819 | G31: =GEOMEAN(G4:G30) -> 4.2576781 | H31: =GEOMEAN(H4:H30) -> 4.0658404 | ... M31: =GEOMEAN(M4:M30) -> 3.4567304
A34: Honor of Kings
A35: Grafis & Desain | B35: Keseimbangan Gameplay | C35: Popularitas & Komunitas | D35: Stabilitas server/koneksi | E35: Fitur & Mode | F35: Kemudahan Kontrol & UI | G35: Tingkat Kompetitif | H35: Sistem Pembayaran | I35: Ukuran Aplikasi | J35: Lancar di HP Menengah | K35: Fairness F2P | L35: Sosialisasi/Menambah Kenalan | M35: Rekomendasi Untuk Pemula
A36: 5 | B36: 3 | C36: 3 | D36: 3 | E36: 4 | F36: 4 | G36: 3 | H36: 4 | I36: 4 | J36: 3 | K36: 4 | L36: 2 | M36: 2
A37: 5 | B37: 5 | C37: 4 | D37: 5 | E37: 5 | F37: 5 | G37: 5 | H37: 5 | I37: 5 | J37: 4 | K37: 5 | L37: 3 | M37: 3
A38: 4 | B38: 4 | C38: 3 | D38: 2 | E38: 5 | F38: 5 | G38: 4 | H38: 5 | I38: 5 | J38: 2 | K38: 5 | L38: 3 | M38: 3
A39: =GEOMEAN(A36:A38) -> 4.6415888 | B39: =GEOMEAN(B36:B38) -> 3.9148676 | C39: =GEOMEAN(C36:C38) -> 3.3019272 | D39: =GEOMEAN(D36:D38) -> 3.1072325 | E39: =GEOMEAN(E36:E38) -> 4.6415888 | F39: =GEOMEAN(F36:F38) -> 4.6415888 | G39: =GEOMEAN(G36:G38) -> 3.9148676 | H39: =GEOMEAN(H36:H38) -> 4.6415888 | ... M39: =GEOMEAN(M36:M38) -> 2.6207414
A42: Garena AOV
A43: Grafis & Desain | B43: Keseimbangan Gameplay | C43: Popularitas & Komunitas | D43: Stabilitas server/koneksi | E43: Fitur & Mode | F43: Kemudahan Kontrol & UI | G43: Tingkat Kompetitif | H43: Sistem Pembayaran | I43: Ukuran Aplikasi | J43: Lancar di HP Menengah | K43: Fairness F2P | L43: Sosialisasi/Menambah Kenalan | M43: Rekomendasi Untuk Pemula
A44: 4 | B44: 4 | C44: 4 | D44: 4 | E44: 3 | F44: 3 | G44: 4 | H44: 4 | I44: 4 | J44: 4 | K44: 3 | L44: 3 | M44: 4
A45: 4 | B45: 4 | C45: 4 | D45: 3 | E45: 4 | F45: 4 | G45: 4 | H45: 4 | I45: 2 | J45: 3 | K45: 3 | L45: 1 | M45: 1
A46: 5 | B46: 5 | C46: 2 | D46: 3 | E46: 4 | F46: 3 | G46: 5 | H46: 5 | I46: 3 | J46: 3 | K46: 5 | L46: 2 | M46: 5
A47: 2 | B47: 2 | C47: 2 | D47: 2 | E47: 2 | F47: 2 | G47: 2 | H47: 2 | I47: 2 | J47: 2 | K47: 2 | L47: 2 | M47: 2
A48: =GEOMEAN(A44:A47) -> 3.5565588 | B48: =GEOMEAN(B44:B47) -> 3.5565588 | C48: =GEOMEAN(C44:C47) -> 2.8284271 | D48: =GEOMEAN(D44:D47) -> 2.9129506 | E48: =GEOMEAN(E44:E47) -> 3.1301692 | F48: =GEOMEAN(F44:F47) -> 2.9129506 | G48: =GEOMEAN(G44:G47) -> 3.5565588 | H48: =GEOMEAN(H44:H47) -> 3.5565588 | ... M48: =GEOMEAN(M44:M47) -> 2.5148669
A51: League of Legends: Wild Rift
A52: Grafis & Desain | B52: Keseimbangan Gameplay | C52: Popularitas & Komunitas | D52: Stabilitas server/koneksi | E52: Fitur & Mode | F52: Kemudahan Kontrol & UI | G52: Tingkat Kompetitif | H52: Sistem Pembayaran | I52: Ukuran Aplikasi | J52: Lancar di HP Menengah | K52: Fairness F2P | L52: Sosialisasi/Menambah Kenalan | M52: Rekomendasi Untuk Pemula
A53: 4 | B53: 3 | C53: 4 | D53: 3 | E53: 4 | F53: 4 | G53: 4 | H53: 3 | I53: 3 | J53: 4 | K53: 3 | L53: 1 | M53: 1
A54: 5 | B54: 4 | C54: 4 | D54: 5 | E54: 5 | F54: 5 | G54: 5 | H54: 3 | I54: 5 | J54: 2 | K54: 5 | L54: 2 | M54: 3
A55: =GEOMEAN(A53:A54) -> 4.472136 | B55: =GEOMEAN(B53:B54) -> 3.4641016 | C55: =GEOMEAN(C53:C54) -> 4 | D55: =GEOMEAN(D53:D54) -> 3.8729833 | E55: =GEOMEAN(E53:E54) -> 4.472136 | F55: =GEOMEAN(F53:F54) -> 4.472136 | G55: =GEOMEAN(G53:G54) -> 4.472136 | H55: =GEOMEAN(H53:H54) -> 3 | ... M55: =GEOMEAN(M53:M54) -> 1.7320508
A58: Pokémon Unite
A59: Grafis & Desain | B59: Keseimbangan Gameplay | C59: Popularitas & Komunitas | D59: Stabilitas server/koneksi | E59: Fitur & Mode | F59: Kemudahan Kontrol & UI | G59: Tingkat Kompetitif | H59: Sistem Pembayaran | I59: Ukuran Aplikasi | J59: Lancar di HP Menengah | K59: Fairness F2P | L59: Sosialisasi/Menambah Kenalan | M59: Rekomendasi Untuk Pemula
A60: 2 | B60: 2 | C60: 2 | D60: 2 | E60: 2 | F60: 2 | G60: 2 | H60: 2 | I60: 2 | J60: 2 | K60: 2 | L60: 2 | M60: 2
A61: 4 | B61: 3 | C61: 3 | D61: 4 | E61: 3 | F61: 4 | G61: 2 | H61: 4 | I61: 4 | J61: 3 | K61: 3 | L61: 3 | M61: 4
A62: =GEOMEAN(A60:A61) -> 2.8284271 | B62: =GEOMEAN(B60:B61) -> 2.4494897 | C62: =GEOMEAN(C60:C61) -> 2.4494897 | D62: =GEOMEAN(D60:D61) -> 2.8284271 | E62: =GEOMEAN(E60:E61) -> 2.4494897 | F62: =GEOMEAN(F60:F61) -> 2.8284271 | G62: =GEOMEAN(G60:G61) -> 2 | H62: =GEOMEAN(H60:H61) -> 2.8284271 | ... M62: =GEOMEAN(M60:M61) -> 2.8284271
A65: Heroes Evolved
...

Sheet GADA
A1: Studi Kasus:
A2: Banyaknya pilihan game MOBA Mobile dengan karakteristik dan fitur yang beragam membuat mahasiswa sering kesulitan menentukan game mana yang paling sesuai untuk dimainkan bersama teman.
J4: Tahap 1: Menentukan Nilai Geometrik Mean | AC4: Tahap 5: Menghitung Agregasi Bobot terhadap Kriteria
B6: Data Kriteria dan Data Alternatif
J8: Menentukan Nilai Geomterik Mean (GM) | AC8: Langkah 5.1: Menghitung Bobot GADA
B9: Data Kriteria
B10: Kode | C10: Kriteria | E10: Jenis | J10: Alternatif | K10: Kode Kriteria | AC10: Alternatif | AD10: Bobot Alternatif | AF10: Bobot GADA
B11: C1 | C11: Grafis & desain | E11: Benefit | K11: C1 | L11: C2 | M11: C3 | N11: C4 | O11: C5 | P11: C6 | Q11: C7 | R11: C8 | S11: C9 | T11: C10 | U11: C11 | V11: C12 | W11: C13 | AC11: A1 | AD11: =L87/L97 -> 0.09403484 | AF11: =POWER(AD11,1) -> 0.09403484
B12: C2 | C12: Keseimbangan gameplay | E12: Benefit | J12: A1 | K12: 4.2079494 | L12: 3.7932954 | M12: 4.2995074 | N12: 3.5909147 | O12: 4.2780812 | P12: 4.3493819 | Q12: 4.2576781 | R12: 4.0658404 | S12: 4.0622706 | T12: 3.6350235 | U12: 3.7990349 | V12: 3.7027469 | W12: 3.4567304 | AC12: A2 | AD12: =L88/L97 -> 0.097236252 | AF12: =POWER(AD12,1) -> 0.097236252
B13: C3 | C13: Popularitas & komunitas | E13: Benefit | J13: A2 | K13: 4.6415888 | L13: 3.9148676 | M13: 3.3019272 | N13: 3.1072325 | O13: 4.6415888 | P13: 4.6415888 | Q13: 3.9148676 | R13: 4.6415888 | S13: 4.6415888 | T13: 2.8844991 | U13: 4.6415888 | V13: 2.6207414 | W13: 2.6207414 | AC13: A3 | AD13: =L89/L97 -> 0.10251509 | AF13: =POWER(AD13,1) -> 0.10251509
B14: C4 | C14: Stabilitas server/koneksi | E14: Benefit | J14: A3 | K14: 3.5565588 | L14: 3.5565588 | M14: 2.8284271 | N14: 2.9129506 | O14: 3.1301692 | P14: 2.9129506 | Q14: 3.5565588 | R14: 3.5565588 | S14: 2.632148 | T14: 2.9129506 | U14: 3.0800703 | V14: 1.8612097 | W14: 2.5148669 | AC14: A4 | AD14: =L90/L97 -> 0.10463482 | AF14: =POWER(AD14,1) -> 0.10463482
B15: C5 | C15: Fitur & mode | E15: Benefit | J15: A4 | K15: 4.472136 | L15: 3.4641016 | M15: 4 | N15: 3.8729833 | O15: 4.472136 | P15: 4.472136 | Q15: 4.472136 | R15: 3 | S15: 3.8729833 | T15: 2.8284271 | U15: 3.8729833 | V15: 1.4142136 | W15: 1.7320508 | AC15: A5 | AD15: =L91/L97 -> 0.10485449 | AF15: =POWER(AD15,1) -> 0.10485449
B16: C6 | C16: Kemudahan kontrol & UI | E16: Benefit | J16: A5 | K16: 2.8284271 | L16: 2.4494897 | M16: 2.4494897 | N16: 2.8284271 | O16: 2.4494897 | P16: 2.8284271 | Q16: 2 | R16: 2.8284271 | S16: 2.8284271 | T16: 2.4494897 | U16: 2.4494897 | V16: 2.4494897 | W16: 2.8284271 | AC16: A6 | AD16: =L92/L97 -> 0.099164651 | AF16: =POWER(AD16,1) -> 0.099164651
B17: C7 | C17: Tingkat kompetitif | E17: Benefit | J17: A6 | K17: 4 | L17: 4 | M17: 2 | N17: 4 | O17: 4 | P17: 4 | Q17: 4 | R17: 4 | S17: 4 | T17: 3 | U17: 4 | V17: 2 | W17: 3 | AC17: A7 | AD17: =L93/L97 -> 0.096153135 | AF17: =POWER(AD17,1) -> 0.096153135
B18: C8 | C18: Sistem pembayaran | E18: Benefit | J18: A7 | K18: 4 | L18: 4 | M18: 3 | N18: 4 | O18: 4 | P18: 4 | Q18: 4 | R18: 4 | S18: 4 | T18: 4 | U18: 4 | V18: 3 | W18: 3 | AC18: A8 | AD18: =L94/L97 -> 0.1019006 | AF18: =POWER(AD18,1) -> 0.1019006
B19: C9 | C19: Ukuran aplikasi | E19: Benefit | J19: A8 | K19: 3 | L19: 3 | M19: 3 | N19: 3 | O19: 4 | P19: 3 | Q19: 4 | R19: 4 | S19: 4 | T19: 4 | U19: 4 | V19: 3 | W19: 2 | AC19: A9 | AD19: =L95/L97 -> 0.10535374 | AF19: =POWER(AD19,1) -> 0.10535374
B20: C10 | C20: Lancar di HP menengah | E20: Benefit | J20: A9 | K20: 2 | L20: 2 | M20: 3 | N20: 3 | O20: 3 | P20: 2 | Q20: 3 | R20: 2 | S20: 3 | T20: 3 | U20: 3 | V20: 3 | W20: 3 | AC20: A10 | AD20: =L96/L97 -> 0.094152375 | AF20: =POWER(AD20,1) -> 0.094152375
B21: C11 | C21: Fairness F2P | E21: Benefit | J21: A10 | K21: 4 | L21: 3.6342412 | M21: 3.3019272 | N21: 4 | O21: 3.6342412 | P21: 3.6342412 | Q21: 3.6342412 | R21: 4 | S21: 3.6342412 | T21: 3.6342412 | U21: 3.6342412 | V21: 3.6342412 | W21: 4 | AC21: Total | AF21: =SUM(AF11:AF20) -> 1
B22: C12 | C22: Sosialisasi / menambah kenalan | E22: Benefit | J22: GM Max | K22: =MAX(K12:K21) -> 4.6415888 | L22: =MAX(L12:L21) -> 4 | M22: =MAX(M12:M21) -> 4.2995074 | N22: =MAX(N12:N21) -> 4 | O22: =MAX(O12:O21) -> 4.6415888 | P22: =MAX(P12:P21) -> 4.6415888 | Q22: =MAX(Q12:Q21) -> 4.472136 | R22: =MAX(R12:R21) -> 4.6415888 | ... W22: =MAX(W12:W21) -> 4
B23: C13 | C23: Rekomendasi untuk pemula | E23: Benefit
AC24: Langkah 5.2: Menghitung Bobot Relatif Keseluruhan
AC26: Alternatif | AD26: Bobot GADA | AF26: Bobot Akhir
B27: Data Alternatif | J27: Tahap 2: Menentukan Nilai Matriks Perbandingan Berpasangan | AC27: A1 | AD27: =AF11 -> 0.09403484 | AF27: =AD27/AF21 -> 0.09403484
B28: Kode | C28: Alternatif | AC28: A2 | AD28: =AF12 -> 0.097236252 | AF28: =AD28/AF21 -> 0.097236252
B29: A1 | C29: Mobile Legends: Bang Bang | AC29: A3 | AD29: =AF13 -> 0.10251509 | AF29: =AD29/AF21 -> 0.10251509
B30: A2 | C30: Honor of Kings | AC30: A4 | AD30: =AF14 -> 0.10463482 | AF30: =AD30/AF21 -> 0.10463482
B31: A3 | C31: Garena AOV | J31: Langkah 2.1 Menghitung Nilai Komponen Alternatif | AC31: A5 | AD31: =AF15 -> 0.10485449 | AF31: =AD31/AF21 -> 0.10485449
B32: A4 | C32: League of Legends: Wild Rift | AC32: A6 | AD32: =AF16 -> 0.099164651 | AF32: =AD32/AF21 -> 0.099164651
B33: A5 | C33: Pokémon Unite | J33: Alternatif | K33: Kode Kriteria | AC33: A7 | AD33: =AF17 -> 0.096153135 | AF33: =AD33/AF21 -> 0.096153135
B34: A6 | C34: Heroes Evolved | K34: C1 | L34: C2 | M34: C3 | N34: C4 | O34: C5 | P34: C6 | Q34: C7 | R34: C8 | S34: C9 | T34: C10 | U34: C11 | V34: C12 | W34: C13 | AC34: A8 | AD34: =AF18 -> 0.1019006 | AF34: =AD34/AF21 -> 0.1019006
B35: A7 | C35: Onmyoji Arena | J35: A1 | K35: =K12 / K22 -> 0.90657521 | L35: =L12/L22 -> 0.94832385 | M35: =M12/M22 -> 1 | N35: =N12/N22 -> 0.89772868 | O35: =O12/O22 -> 0.92168466 | P35: =P12/P22 -> 0.93704593 | Q35: =Q12/Q22 -> 0.95204577 | R35: =R12/R22 -> 0.87595875 | S35: =S12/S22 -> 0.87518966 | ... W35: =W12/W22 -> 0.8641826 | AC35: A9 | AD35: =AF19 -> 0.10535374 | AF35: =AD35/AF21 -> 0.10535374
B36: A8 | C36: Lokapala | J36: A2 | K36: =K13/ K22 -> 1 | L36: =L13/L22 -> 0.97871691 | M36: =M13/M22 -> 0.76797803 | N36: =N13/N22 -> 0.77680813 | O36: =O13/O22 -> 1 | P36: =P13/P22 -> 1 | Q36: =Q13/Q22 -> 0.87539102 | R36: =R13/R22 -> 1 | S36: =S13/S22 -> 1 | ... W36: =W13/W22 -> 0.65518535 | AC36: A10 | AD36: =AF20 -> 0.094152375 | AF36: =AD36/AF21 -> 0.094152375
B37: A9 | C37: Vainglory (IOS) | J37: A3 | K37: =K14 / K22 -> 0.76623737 | L37: =L14/L22 -> 0.8891397 | M37: =M14/M22 -> 0.6578491 | N37: =N14/N22 -> 0.72823766 | O37: =O14/O22 -> 0.6743745 | P37: =P14/P22 -> 0.62757619 | Q37: =Q14/Q22 -> 0.79527073 | R37: =R14/R22 -> 0.76623737 | S37: =S14/S22 -> 0.5670791 | ... W37: =W14/W22 -> 0.62871671
B38: A10 | C38: Marvel Super War | J38: A4 | K38: =K15 / K22 -> 0.96349248 | L38: =L15/L22 -> 0.8660254 | M38: =M15/M22 -> 0.93033913 | N38: =N15/N22 -> 0.96824584 | O38: =O15/O22 -> 0.96349248 | P38: =P15/P22 -> 0.96349248 | Q38: =Q15/Q22 -> 1 | R38: =R15/R22 -> 0.64633041 | S38: =S15/S22 -> 0.83440897 | ... W38: =W15/W22 -> 0.4330127
J39: A5 | K39: =K16 / K22 -> 0.60936615 | L39: =L16/L22 -> 0.61237244 | M39: =M16/M22 -> 0.56971404 | N39: =N16/N22 -> 0.70710678 | O39: =O16/O22 -> 0.52772657 | P39: =P16/P22 -> 0.60936615 | Q39: =Q16/Q22 -> 0.4472136 | R39: =R16/R22 -> 0.60936615 | S39: =S16/S22 -> 0.60936615 | ... W39: =W16/W22 -> 0.70710678
J40: A6 | K40: =K17/ K22 -> 0.86177388 | L40: =L17/L22 -> 1 | M40: =M17/M22 -> 0.46516956 | N40: =N17/N22 -> 1 | O40: =O17/O22 -> 0.86177388 | P40: =P17/P22 -> 0.86177388 | Q40: =Q17/Q22 -> 0.89442719 | R40: =R17/R22 -> 0.86177388 | S40: =S17/S22 -> 0.86177388 | ... W40: =W17/W22 -> 0.75
J41: A7 | K41: =K18 / K22 -> 0.86177388 | L41: =L18/L22 -> 1 | M41: =M18/M22 -> 0.69775434 | N41: =N18/N22 -> 1 | O41: =O18/O22 -> 0.86177388 | P41: =P18/P22 -> 0.86177388 | Q41: =Q18/Q22 -> 0.89442719 | R41: =R18/R22 -> 0.86177388 | S41: =S18/S22 -> 0.86177388 | ... W41: =W18/W22 -> 0.75 | AC41: Tahap 6: Menghitung Hasil Perangkingan
G42: Keterangan: | J42: A8 | K42: =K19 / K22 -> 0.64633041 | L42: =L19/L22 -> 0.75 | M42: =M19/M22 -> 0.69775434 | N42: =N19/N22 -> 0.75 | O42: =O19/O22 -> 0.86177388 | P42: =P19/P22 -> 0.64633041 | Q42: =Q19/Q22 -> 0.89442719 | R42: =R19/R22 -> 0.86177388 | S42: =S19/S22 -> 0.86177388 | ... W42: =W19/W22 -> 0.5
G43: Karena semua kriteria bersifat benefit | J43: A9 | K43: =K20 / K22 -> 0.43088694 | L43: =L20/L22 -> 0.5 | M43: =M20/M22 -> 0.69775434 | N43: =N20/N22 -> 0.75 | O43: =O20/O22 -> 0.64633041 | P43: =P20/P22 -> 0.43088694 | Q43: =Q20/Q22 -> 0.67082039 | R43: =R20/R22 -> 0.43088694 | S43: =S20/S22 -> 0.64633041 | ... W43: =W20/W22 -> 0.75
J44: A10 | K44: =K21 / K22 -> 0.86177388 | L44: =L21/L22 -> 0.9085603 | M44: =M21/M22 -> 0.76797803 | N44: =N21/N22 -> 1 | O44: =O21/O22 -> 0.78297353 | P44: =P21/P22 -> 0.78297353 | Q44: =Q21/Q22 -> 0.81264103 | R44: =R21/R22 -> 0.86177388 | S44: =S21/S22 -> 0.78297353 | ... W44: =W21/W22 -> 1 | AC44: RANK | AD44: Kode | AE44: Alternatif | AG44: Bobot Akhir | AI44: Keterangan
...
